I'm sorry, but an uncaught exception occurred.

While running game code:
  File "game/minigame_script.rpy", line 260, in script
    d "Game Over"
Exception: Sayer 'd' is not defined.

-- Full Traceback ------------------------------------------------------------

Full traceback:
  File "game/minigame_script.rpy", line 260, in script
    d "Game Over"
  File "C:\Users\s02li\Downloads\renpy-8.2.0-sdk\renpy\ast.py", line 2557, in execute
    Say.execute(self)
  File "C:\Users\s02li\Downloads\renpy-8.2.0-sdk\renpy\ast.py", line 575, in execute
    who = eval_who(self.who, self.who_fast)
  File "C:\Users\s02li\Downloads\renpy-8.2.0-sdk\renpy\ast.py", line 464, in eval_who
    raise Exception("Sayer '%s' is not defined." % who)
Exception: Sayer 'd' is not defined.

Windows-10-10.0.22631 AMD64
Ren'Py 8.2.0.24012702
AcademicDishonesty 1.0
Sun Feb 25 19:20:10 2024
